Workbook
Name [資料表詳細]cmft_account: 資料表詳細!$C$148
Name [資料表詳細]cmft_device: 資料表詳細!#REF!
Name [資料表詳細]cmft_oper: 資料表詳細!$C$124
Name [資料表詳細]cmft_role: 資料表詳細!$C$133
Name [資料表詳細]cmft_role_auth: 資料表詳細!$C$140
Name [資料表詳細]dlts_caller_display: 資料表詳細!$C$361
Name [資料表詳細]dlts_caller_log: 資料表詳細!$C$368
Name [資料表詳細]dlts_seat_status: 資料表詳細!$C$353
Name [資料表詳細]dmd_char_blocklist: 資料表詳細!#REF!
Name [資料表詳細]dmd_group: 資料表詳細!$C$242
Name [資料表詳細]dmd_group_target: 資料表詳細!$C$249
Name [資料表詳細]dmd_instant_message: 資料表詳細!$C$276
Name [資料表詳細]dmd_playlist: 資料表詳細!$C$314
Name [資料表詳細]dmd_power_setting: 資料表詳細!$C$343
Name [資料表詳細]dmd_pre_record_message: 資料表詳細!$C$257
Name [資料表詳細]dmd_schedule: 資料表詳細!$C$325
Name [資料表詳細]dmd_schedule_playlist: 資料表詳細!$C$334
Name [資料表詳細]dmd_target: 資料表詳細!$C$232
Name [資料表詳細]dmd_train_message: 資料表詳細!$C$294
Name [資料表詳細]otcs_equip_status: 資料表詳細!#REF!
Name [資料表詳細]otcs_event: 資料表詳細!$C$410
Name [資料表詳細]otcs_event_list: 資料表詳細!$C$400
Name [資料表詳細]otcs_pre_record_message: 資料表詳細!#REF!
Name [資料表詳細]otcs_train: 資料表詳細!$C$377
Name [資料表詳細]pa_daypart_time: 資料表詳細!$C$222
Name [資料表詳細]pa_daypart_volume: 資料表詳細!$C$215
Name [資料表詳細]pa_group: 資料表詳細!$C$166
Name [資料表詳細]pa_group_target: 資料表詳細!$C$173
Name [資料表詳細]pa_pre_record_voice: 資料表詳細!$C$180
Name [資料表詳細]pa_schedule: 資料表詳細!$C$197
Name [資料表詳細]pa_schedule_playlist: 資料表詳細!$C$206
Name [資料表詳細]pa_target: 資料表詳細!$C$159
Name [資料表詳細]seat_equip: 資料表詳細!$C$115
Name [資料表詳細]sync_linked_setting: 資料表詳細!$C$433
Name [資料表詳細]sys_alarm: 資料表詳細!$C$59
Name [資料表詳細]sys_alarm_history: 資料表詳細!$C$71
Name [資料表詳細]sys_alarm_list: 資料表詳細!$C$46
Name [資料表詳細]sys_config: 資料表詳細!$C$4
Name [資料表詳細]sys_equip: 資料表詳細!$C$88
Name [資料表詳細]sys_equip_catalog: 資料表詳細!#REF!
Name [資料表詳細]sys_location: 資料表詳細!#REF!
Name [資料表詳細]sys_oper_alarm_list: 資料表詳細!$C$46
Name [資料表詳細]sys_oper_log: 資料表詳細!$C$28
Name [資料表詳細]sys_oper_log_history: 資料表詳細!$C$37
Name [資料表詳細]sys_seat: 資料表詳細!$C$103
Name [資料表詳細]sys_seat_equip: 資料表詳細!$C$115
Name [資料表詳細]sys_station: 資料表詳細!$C$13
Name [資料表詳細]sys_station_area: 資料表詳細!$C$21
Name 車站區域_LG01: #REF!
Name 車站區域_LG02: #REF!
Name 車站區域_LG03: #REF!
Name 車站區域_LG04: #REF!
Name 車站區域_LG05: #REF!
Name 車站區域_LG06: #REF!
Name 車站區域_LG07: #REF!
Name 車站區域_LG08: #REF!
Name 車站區域_LG08A: #REF!
Name 車站區域_LG09: #REF!
Name 選單_CMFT設備: 選單!#REF!
Name 選單_主畫面_中: 選單!$V$3:$V$10

Sheet 資料表一覽
A1: 資料表一覽 | G1: HMI使用權限
A2: 資料表類別 | B2: 資料表序號 | C2: 資料表名稱(英) | D2: 資料表名稱(中) | E2: 備考 | F2: 資料表數據(綠色代表資料筆數固定) | G2: 新增 | H2: 編輯 | I2: 刪除
A3: System | B3: 1 | C3: sys_config | D3: 系統設定列表 | E3: 固定數量資料(需確認),可於CMFT手動編輯內容,但不可新增刪除,目前為臨時假數據 | F3: sys_config | G3: X | H3: X | I3: X
A4: System | B4: 2 | C4: sys_station | D4: 車站列表 | E4: 所有車站的資料 | F4: sys_station | G4: X | H4: X | I4: X
A5: System | B5: 3 | C5: sys_station_area | D5: 車站區域列表 | E5: 所有車站的區域資料 | F5: sys_station_area | G5: X | H5: X | I5: X
A6: System | B6: 4 | C6: sys_oper_log | D6: 使用者操作紀錄列表 | E6: CMFT操作人員所做的所有操作(30天內) | G6: ◯ | H6: X | I6: X
A7: System | B7: 5 | C7: sys_oper_log_history | D7: 使用者操作紀錄列表(歷史紀錄) | E7: CMFT操作人員所做的所有操作(超過30天) | G7: X | H7: X | I7: X
A8: System | B8: 6 | C8: sys_alarm_list | D8: 告警定義列表 | E8: 所有告警的樣式 | F8: sys_alarm_list | G8: X | H8: X | I8: X
A9: System | B9: 7 | C9: sys_alarm | D9: 告警列表 | E9: 近期告警紀錄,CMFT操作人員可改變確認狀態 | F9: sys_alarm | G9: X | H9: ◯ | I9: X
A10: System | B10: 8 | C10: sys_alarm_history | D10: 告警列表(歷史紀錄) | E10: 歷史告警紀錄,供CMFT操作人員查找 | G10: X | H10: X | I10: X
A11: System | B11: 9 | C11: sys_region | D11: 區域列表 | G11: X | H11: X | I11: X
A12: System | B12: 10 | C12: sys_equip_status | D12: 設備狀態列表 | E12: 所有設備詳細資料 | F12: sys_equip_status | G12: X | H12: X | I12: X
A13: System | B13: 11 | C13: sys_seat | D13: 席位列表 | E13: 席位資訊 | F13: sys_seate | G13: X | H13: X | I13: X
A14: System | B14: 12 | C14: sys_seat_equip | D14: 席位設備列表 | E14: 席位的所有設備資訊 | G14: X | H14: X | I14: X
A15: CMFT | B15: 13 | C15: cmft_oper | D15: CMFT功能列表 | E15: CMFT的所有功能列表 | F15: cmft_oper | G15: X | H15: X | I15: X
A16: CMFT | B16: 14 | C16: cmft_role | D16: CMFT角色列表 | E16: 角色列表 | F16: cmft_role | G16: ◯ | H16: ◯ | I16: ◯
A17: CMFT | B17: 15 | C17: cmft_role_auth | D17: CMFT角色操作權限設定列表 | E17: 角色權限列表 | F17: cmft_role_auth | G17: ◯ | H17: ◯ | I17: ◯
A18: CMFT | B18: 16 | C18: cmft_account | D18: CMFT帳號列表 | E18: CMFT操作員帳號 | F18: cmft_account | G18: ◯ | H18: ◯ | I18: ◯
A19: PA | B19: 17 | C19: pa_target | D19: 廣播對象列表 | E19: 廣播的選擇對象列表(以區域為單位) | F19: pa_target | G19: X | H19: X | I19: X
A20: PA | B20: 18 | C20: pa_group | D20: 廣播群組設定 | E20: 廣播群組列表 | G20: ◯ | H20: ◯ | I20: ◯
A21: PA | B21: 19 | C21: pa_group_target | D21: 廣播群組對象 | E21: 廣播群組的對象資料 | G21: ◯ | H21: ◯ | I21: ◯
A22: PA | B22: 20 | C22: pa_pre_record_voice | D22: 廣播預錄音檔列表 | E22: 廣播的預錄音檔,CMFT操作人員僅可編輯預錄廣播的名稱 | F22: pa_pre_record_voice | G22: X | H22: ◯ | I22: X
A23: PA | B23: 21 | C23: pa_schedule | D23: 廣播預錄語音排程 | E23: 廣播的語音排程 | G23: ◯ | H23: ◯ | I23: ◯
A24: PA | B24: 22 | C24: pa_schedule_playlist | D24: 廣播預錄語音播放內容 | E24: 廣播語音排程的語音列表及選擇對象列表 | G24: ◯ | H24: ◯ | I24: ◯
A25: PA | B25: 23 | C25: pa_daypart_volume | D25: 廣播時段音量 | E25: 各車站的尖峰/離峰/夜間時段的音量, 資料筆數為(車站數量)*3 | F25: pa_daypart_volume | G25: X | H25: ◯ | I25: X
A26: PA | B26: 24 | C26: pa_daypart_time | D26: 廣播分時時間 | E26: 記錄各車站的所有尖峰及夜間時刻 | G26: ◯ | H26: ◯ | I26: ◯
A27: DMD | B27: 25 | C27: dmd_target | D27: 點矩陣對象列表 | E27: 為固定數量資料,目前insert數據為實際數據 | F27: dmd_target | G27: X | H27: X | I27: X
A28: DMD | B28: 26 | C28: dmd_group | D28: 點矩陣群組設定 | G28: ◯ | H28: ◯ | I28: ◯
A29: DMD | B29: 27 | C29: dmd_group_target | D29: 點矩陣群組對象 | G29: ◯ | H29: ◯ | I29: ◯
A30: DMD | B30: 28 | C30: dmd_pre_record_message | D30: 點矩陣預錄訊息列表 | F30: dmd_pre_record_message | G30: ◯ | H30: ◯ | I30: ◯
A31: DMD | B31: 29 | C31: dmd_instant_message | D31: 點矩陣即時訊息列表 | E31: 存放要發送之即時訊息內容,供server取用 | G31: ◯ | H31: X | I31: X
A32: DMD | B32: 30 | C32: dmd_train_message | D32: 點矩陣列車訊息 | E32: 列車用預錄訊息內容,為固定數量,可供CMFT操作員編輯 | F32: dmd_train_message | G32: X | H32: ◯ | I32: X
A33: DMD | B33: 31 | C33: dmd_playlist | D33: 點矩陣播放內容 | E33: 存放即時的已發送內容 | F33: dmd_playlist | G33: X | H33: X | I33: X
A34: DMD | B34: 32 | C34: dmd_schedule | D34: 點矩陣預錄訊息排程 | E34: 點矩陣的訊息排程 | G34: ◯ | H34: ◯ | I34: ◯
A35: DMD | B35: 33 | C35: dmd_schedule_playlist | D35: 點矩陣預錄訊息播放內容 | E35: 點矩陣的訊息排程的放內容 | G35: ◯ | H35: ◯ | I35: ◯
A36: DMD | B36: 34 | C36: dmd_power_setting | D36: 點矩陣電源設定 | G36: ◯ | H36: X | I36: ◯
A37: DLTS | B37: 36 | C37: dlts_seat_status | D37: 直線電話席位通話狀態 | F37: dlts_seat_status | G37: X | H37: X | I37: X
A38: DLTS | B38: 37 | C38: dlts_caller_display | D38: 直線電話來電顯示 | F38: dlts_caller_display | G38: X | H38: X | I38: X
A39: DLTS | B39: 38 | C39: dlts_caller_log | D39: 直線電話通話紀錄 | F39: dlts_caller_log | G39: X | H39: X | I39: X
A40: OTCS | B40: 39 | C40: otcs_train | D40: 列車列表
...

Sheet 資料表詳細
A1: 資料表詳細
A2: 資料表(Postgre) | L2: 模型(C#)
A3: 排序 | B3: 資料表分類 | C3: 表名 | D3: 欄位序號 | E3: 欄位名稱(英) | F3: 欄位名稱(中) | G3: 屬性類型(Postgre) | H3: 長度 | I3: 空值 | J3: 設定(PK/FK) | K3: 備註 | L3: 類名 | M3: 屬性類型(C#) | N3: 屬性名(Csharp)
A4: 1 | B4: System | C4: sys_config | D4: 1 | E4: config_name | F4: 系統參數名稱 | G4: character varying | H4: 30 | I4: N | J4: PK | L4: =CONCATENATE(參考!B$1,[資料表詳細]資料表詳細表格[[#This Row],[表名]]) -> sys_config | M4: =VLOOKUP([資料表詳細]資料表詳細表格[[#This Row],[屬性類型(Postgre)]],選單!$A$3:$B$20,2,FALSE) -> string | N4: =CONCATENATE(參考!B$2,[資料表詳細]資料表詳細表格[[#This Row],[欄位名稱(英)]]) -> config_name
A5: 2 | B5: System | C5: sys_config | D5: 2 | E5: config_value | F5: 系統參數值 | G5: text | I5: Y | L5: =CONCATENATE(參考!B$1,[資料表詳細]資料表詳細表格[[#This Row],[表名]]) -> sys_config | M5: =VLOOKUP([資料表詳細]資料表詳細表格[[#This Row],[屬性類型(Postgre)]],選單!$A$3:$B$20,2,FALSE) -> string | N5: =CONCATENATE(參考!B$2,[資料表詳細]資料表詳細表格[[#This Row],[欄位名稱(英)]]) -> config_value
A6: 3 | B6: System | C6: sys_config | D6: 3 | E6: config_description | F6: 系統參數說明 | G6: text | I6: Y | L6: =CONCATENATE(參考!B$1,[資料表詳細]資料表詳細表格[[#This Row],[表名]]) -> sys_config | M6: =VLOOKUP([資料表詳細]資料表詳細表格[[#This Row],[屬性類型(Postgre)]],選單!$A$3:$B$20,2,FALSE) -> string | N6: =CONCATENATE(參考!B$2,[資料表詳細]資料表詳細表格[[#This Row],[欄位名稱(英)]]) -> config_description
A7: 4 | B7: System | C7: sys_config | D7: 4 | E7: system_id | F7: 所屬系統編號 | G7: character varying | H7: 20 | I7: N | L7: =CONCATENATE(參考!B$1,[資料表詳細]資料表詳細表格[[#This Row],[表名]]) -> sys_config | M7: =VLOOKUP([資料表詳細]資料表詳細表格[[#This Row],[屬性類型(Postgre)]],選單!$A$3:$B$20,2,FALSE) -> string | N7: =CONCATENATE(參考!B$2,[資料表詳細]資料表詳細表格[[#This Row],[欄位名稱(英)]]) -> system_id
A8: 5 | B8: System | C8: sys_config | D8: 5 | E8: remark | F8: 備註 | G8: text | I8: Y | L8: =CONCATENATE(參考!B$1,[資料表詳細]資料表詳細表格[[#This Row],[表名]]) -> sys_config | M8: =VLOOKUP([資料表詳細]資料表詳細表格[[#This Row],[屬性類型(Postgre)]],選單!$A$3:$B$20,2,FALSE) -> string | N8: =CONCATENATE(參考!B$2,[資料表詳細]資料表詳細表格[[#This Row],[欄位名稱(英)]]) -> remark
A9: 6 | B9: System | C9: sys_config | D9: 6 | E9: ins_user | F9: 資料新增人員 | G9: character varying | H9: 20 | I9: N | L9: =CONCATENATE(參考!B$1,[資料表詳細]資料表詳細表格[[#This Row],[表名]]) -> sys_config | M9: =VLOOKUP([資料表詳細]資料表詳細表格[[#This Row],[屬性類型(Postgre)]],選單!$A$3:$B$20,2,FALSE) -> string | N9: =CONCATENATE(參考!B$2,[資料表詳細]資料表詳細表格[[#This Row],[欄位名稱(英)]]) -> ins_user
A10: 7 | B10: System | C10: sys_config | D10: 7 | E10: ins_time | F10: 資料新增時間 | G10: timestamp without time zone | I10: N | L10: =CONCATENATE(參考!B$1,[資料表詳細]資料表詳細表格[[#This Row],[表名]]) -> sys_config | M10: =VLOOKUP([資料表詳細]資料表詳細表格[[#This Row],[屬性類型(Postgre)]],選單!$A$3:$B$20,2,FALSE) -> DateTime | N10: =CONCATENATE(參考!B$2,[資料表詳細]資料表詳細表格[[#This Row],[欄位名稱(英)]]) -> ins_time
A11: 8 | B11: System | C11: sys_config | D11: 8 | E11: upd_user | F11: 資料修改人員 | G11: character varying | H11: 20 | I11: N | L11: =CONCATENATE(參考!B$1,[資料表詳細]資料表詳細表格[[#This Row],[表名]]) -> sys_config | M11: =VLOOKUP([資料表詳細]資料表詳細表格[[#This Row],[屬性類型(Postgre)]],選單!$A$3:$B$20,2,FALSE) -> string | N11: =CONCATENATE(參考!B$2,[資料表詳細]資料表詳細表格[[#This Row],[欄位名稱(英)]]) -> upd_user
A12: 9 | B12: System | C12: sys_config | D12: 9 | E12: upd_time | F12: 資料修改時間 | G12: timestamp without time zone | I12: N | L12: =CONCATENATE(參考!B$1,[資料表詳細]資料表詳細表格[[#This Row],[表名]]) -> sys_config | M12: =VLOOKUP([資料表詳細]資料表詳細表格[[#This Row],[屬性類型(Postgre)]],選單!$A$3:$B$20,2,FALSE) -> DateTime | N12: =CONCATENATE(參考!B$2,[資料表詳細]資料表詳細表格[[#This Row],[欄位名稱(英)]]) -> upd_time
A13: 10 | B13: System | C13: sys_station | D13: 1 | E13: station_id | F13: 車站編號 | G13: character varying | H13: 10 | I13: N | J13: PK | L13: =CONCATENATE(參考!B$1,[資料表詳細]資料表詳細表格[[#This Row],[表名]]) -> sys_station | M13: =VLOOKUP([資料表詳細]資料表詳細表格[[#This Row],[屬性類型(Postgre)]],選單!$A$3:$B$20,2,FALSE) -> string | N13: =CONCATENATE(參考!B$2,[資料表詳細]資料表詳細表格[[#This Row],[欄位名稱(英)]]) -> station_id
A14: 11 | B14: System | C14: sys_station | D14: 2 | E14: station_name | F14: 車站名稱 | G14: character varying | H14: 20 | I14: N | L14: =CONCATENATE(參考!B$1,[資料表詳細]資料表詳細表格[[#This Row],[表名]]) -> sys_station | M14: =VLOOKUP([資料表詳細]資料表詳細表格[[#This Row],[屬性類型(Postgre)]],選單!$A$3:$B$20,2,FALSE) -> string | N14: =CONCATENATE(參考!B$2,[資料表詳細]資料表詳細表格[[#This Row],[欄位名稱(英)]]) -> station_name
A15: 12 | B15: System | C15: sys_station | D15: 3 | E15: station_name_eng | F15: 車站英文名稱 | G15: text | I15: N | L15: =CONCATENATE(參考!B$1,[資料表詳細]資料表詳細表格[[#This Row],[表名]]) -> sys_station | M15: =VLOOKUP([資料表詳細]資料表詳細表格[[#This Row],[屬性類型(Postgre)]],選單!$A$3:$B$20,2,FALSE) -> string | N15: =CONCATENATE(參考!B$2,[資料表詳細]資料表詳細表格[[#This Row],[欄位名稱(英)]]) -> station_name_eng
A16: 13 | B16: System | C16: sys_station | D16: 4 | E16: remark | F16: 備註 | G16: text | I16: Y | L16: =CONCATENATE(參考!B$1,[資料表詳細]資料表詳細表格[[#This Row],[表名]]) -> sys_station | M16: =VLOOKUP([資料表詳細]資料表詳細表格[[#This Row],[屬性類型(Postgre)]],選單!$A$3:$B$20,2,FALSE) -> string | N16: =CONCATENATE(參考!B$2,[資料表詳細]資料表詳細表格[[#This Row],[欄位名稱(英)]]) -> remark
A17: 14 | B17: System | C17: sys_station | D17: 5 | E17: ins_user | F17: 資料新增人員 | G17: character varying | H17: 20 | I17: N | L17: =CONCATENATE(參考!B$1,[資料表詳細]資料表詳細表格[[#This Row],[表名]]) -> sys_station | M17: =VLOOKUP([資料表詳細]資料表詳細表格[[#This Row],[屬性類型(Postgre)]],選單!$A$3:$B$20,2,FALSE) -> string | N17: =CONCATENATE(參考!B$2,[資料表詳細]資料表詳細表格[[#This Row],[欄位名稱(英)]]) -> ins_user
A18: 15 | B18: System | C18: sys_station | D18: 6 | E18: ins_time | F18: 資料新增時間 | G18: timestamp without time zone | I18: N | L18: =CONCATENATE(參考!B$1,[資料表詳細]資料表詳細表格[[#This Row],[表名]]) -> sys_station | M18: =VLOOKUP([資料表詳細]資料表詳細表格[[#This Row],[屬性類型(Postgre)]],選單!$A$3:$B$20,2,FALSE) -> DateTime | N18: =CONCATENATE(參考!B$2,[資料表詳細]資料表詳細表格[[#This Row],[欄位名稱(英)]]) -> ins_time
A19: 16 | B19: System | C19: sys_station | D19: 7 | E19: upd_user | F19: 資料修改人員 | G19: character varying | H19: 20 | I19: N | L19: =CONCATENATE(參考!B$1,[資料表詳細]資料表詳細表格[[#This Row],[表名]]) -> sys_station | M19: =VLOOKUP([資料表詳細]資料表詳細表格[[#This Row],[屬性類型(Postgre)]],選單!$A$3:$B$20,2,FALSE) -> string | N19: =CONCATENATE(參考!B$2,[資料表詳細]資料表詳細表格[[#This Row],[欄位名稱(英)]]) -> upd_user
A20: 17 | B20: System | C20: sys_station | D20: 8 | E20: upd_time | F20: 資料修改時間 | G20: timestamp without time zone | I20: N | L20: =CONCATENATE(參考!B$1,[資料表詳細]資料表詳細表格[[#This Row],[表名]]) -> sys_station | M20: =VLOOKUP([資料表詳細]資料表詳細表格[[#This Row],[屬性類型(Postgre)]],選單!$A$3:$B$20,2,FALSE) -> DateTime | N20: =CONCATENATE(參考!B$2,[資料表詳細]資料表詳細表格[[#This Row],[欄位名稱(英)]]) -> upd_time
A21: 18 | B21: System | C21: sys_station_area | D21: 1 | E21: station_id | F21: 車站編號 | G21: character varying | H21: 10 | I21: N | J21: PK | L21: =CONCATENATE(參考!B$1,[資料表詳細]資料表詳細表格[[#This Row],[表名]]) -> sys_station_area | M21: =VLOOKUP([資料表詳細]資料表詳細表格[[#This Row],[屬性類型(Postgre)]],選單!$A$3:$B$20,2,FALSE) -> string | N21: =CONCATENATE(參考!B$2,[資料表詳細]資料表詳細表格[[#This Row],[欄位名稱(英)]]) -> station_id
A22: 19 | B22: System | C22: sys_station_area | D22: 2 | E22: area_id | F22: 車站區域編號 | G22: character varying | H22: 10 | I22: N | J22: PK | L22: =CONCATENATE(參考!B$1,[資料表詳細]資料表詳細表格[[#This Row],[表名]]) -> sys_station_area | M22: =VLOOKUP([資料表詳細]資料表詳細表格[[#This Row],[屬性類型(Postgre)]],選單!$A$3:$B$20,2,FALSE) -> string | N22: =CONCATENATE(參考!B$2,[資料表詳細]資料表詳細表格[[#This Row],[欄位名稱(英)]]) -> area_id
A23: 20 | B23: System | C23: sys_station_area | D23: 3 | E23: area_name | F23: 車站區域名稱 | G23: character varying | H23: 40 | I23: N | L23: =CONCATENATE(參考!B$1,[資料表詳細]資料表詳細表格[[#This Row],[表名]]) -> sys_station_area | M23: =VLOOKUP([資料表詳細]資料表詳細表格[[#This Row],[屬性類型(Postgre)]],選單!$A$3:$B$20,2,FALSE) -> string | N23: =CONCATENATE(參考!B$2,[資料表詳細]資料表詳細表格[[#This Row],[欄位名稱(英)]]) -> area_name
A24: 21 | B24: System | C24: sys_station_area | D24: 4 | E24: ins_user | F24: 資料新增人員 | G24: character varying | H24: 20 | I24: N | L24: =CONCATENATE(參考!B$1,[資料表詳細]資料表詳細表格[[#This Row],[表名]]) -> sys_station_area | M24: =VLOOKUP([資料表詳細]資料表詳細表格[[#This Row],[屬性類型(Postgre)]],選單!$A$3:$B$20,2,FALSE) -> string | N24: =CONCATENATE(參考!B$2,[資料表詳細]資料表詳細表格[[#This Row],[欄位名稱(英)]]) -> ins_user
A25: 22 | B25: System | C25: sys_station_area | D25: 5 | E25: ins_time | F25: 資料新增時間 | G25: timestamp without time zone | I25: N | L25: =CONCATENATE(參考!B$1,[資料表詳細]資料表詳細表格[[#This Row],[表名]]) -> sys_station_area | M25: =VLOOKUP([資料表詳細]資料表詳細表格[[#This Row],[屬性類型(Postgre)]],選單!$A$3:$B$20,2,FALSE) -> DateTime | N25: =CONCATENATE(參考!B$2,[資料表詳細]資料表詳細表格[[#This Row],[欄位名稱(英)]]) -> ins_time
A26: 23 | B26: System | C26: sys_station_area | D26: 6 | E26: upd_user | F26: 資料修改人員 | G26: character varying | H26: 20 | I26: N | L26: =CONCATENATE(參考!B$1,[資料表詳細]資料表詳細表格[[#This Row],[表名]]) -> sys_station_area | M26: =VLOOKUP([資料表詳細]資料表詳細表格[[#This Row],[屬性類型(Postgre)]],選單!$A$3:$B$20,2,FALSE) -> string | N26: =CONCATENATE(參考!B$2,[資料表詳細]資料表詳細表格[[#This Row],[欄位名稱(英)]]) -> upd_user
A27: 24 | B27: System | C27: sys_station_area | D27: 7 | E27: upd_time | F27: 資料修改時間 | G27: timestamp without time zone | I27: N | L27: =CONCATENATE(參考!B$1,[資料表詳細]資料表詳細表格[[#This Row],[表名]]) -> sys_station_area | M27: =VLOOKUP([資料表詳細]資料表詳細表格[[#This Row],[屬性類型(Postgre)]],選單!$A$3:$B$20,2,FALSE) -> DateTime | N27: =CONCATENATE(參考!B$2,[資料表詳細]資料表詳細表格[[#This Row],[欄位名稱(英)]]) -> upd_time
A28: 25 | B28: System | C28: sys_oper_log | D28: 1 | E28: log_id | F28: 事件紀錄編號 | G28: uuid | I28: N | J28: PK | L28: =CONCATENATE(參考!B$1,[資料表詳細]資料表詳細表格[[#This Row],[表名]]) -> sys_oper_log | M28: =VLOOKUP([資料表詳細]資料表詳細表格[[#This Row],[屬性類型(Postgre)]],選單!$A$3:$B$20,2,FALSE) -> Guid | N28: =CONCATENATE(參考!B$2,[資料表詳細]資料表詳細表格[[#This Row],[欄位名稱(英)]]) -> log_id
A29: 26 | B29: System | C29: sys_oper_log | D29: 2 | E29: account_id | F29: 使用者帳號 | G29: character varying | H29: 20 | I29: N | L29: =CONCATENATE(參考!B$1,[資料表詳細]資料表詳細表格[[#This Row],[表名]]) -> sys_oper_log | M29: =VLOOKUP([資料表詳細]資料表詳細表格[[#This Row],[屬性類型(Postgre)]],選單!$A$3:$B$20,2,FALSE) -> string | N29: =CONCATENATE(參考!B$2,[資料表詳細]資料表詳細表格[[#This Row],[欄位名稱(英)]]) -> account_id
A30: 27 | B30: System | C30: sys_oper_log | D30: 3 | E30: account_name | F30: 使用者姓名 | G30: text | I30: N | K30: 必須不依賴ID,萬一腳色被刪除仍可查找 | L30: =CONCATENATE(參考!B$1,[資料表詳細]資料表詳細表格[[#This Row],[表名]]) -> sys_oper_log | M30: =VLOOKUP([資料表詳細]資料表詳細表格[[#This Row],[屬性類型(Postgre)]],選單!$A$3:$B$20,2,FALSE) -> string | N30: =CONCATENATE(參考!B$2,[資料表詳細]資料表詳細表格[[#This Row],[欄位名稱(英)]]) -> account_name
A31: 28 | B31: System | C31: sys_oper_log | D31: 4 | E31: oper_id | F31: 操作識別代碼 | G31: character varying | H31: 40 | I31: N | L31: =CONCATENATE(參考!B$1,[資料表詳細]資料表詳細表格[[#This Row],[表名]]) -> sys_oper_log | M31: =VLOOKUP([資料表詳細]資料表詳細表格[[#This Row],[屬性類型(Postgre)]],選單!$A$3:$B$20,2,FALSE) -> string | N31: =CONCATENATE(參考!B$2,[資料表詳細]資料表詳細表格[[#This Row],[欄位名稱(英)]]) -> oper_id
A32: 29 | B32: System | C32: sys_oper_log | D32: 5 | E32: log_content | F32: 事件紀錄內容 | G32: text | I32: N | L32: =CONCATENATE(參考!B$1,[資料表詳細]資料表詳細表格[[#This Row],[表名]]) -> sys_oper_log | M32: =VLOOKUP([資料表詳細]資料表詳細表格[[#This Row],[屬性類型(Postgre)]],選單!$A$3:$B$20,2,FALSE) -> string | N32: =CONCATENATE(參考!B$2,[資料表詳細]資料表詳細表格[[#This Row],[欄位名稱(英)]]) -> log_content
A33: 30 | B33: System | C33: sys_oper_log | D33: 6 | E33: ins_user | F33: 資料新增人員 | G33: character varying | H33: 20 | I33: N | L33: =CONCATENATE(參考!B$1,[資料表詳細]資料表詳細表格[[#This Row],[表名]]) -> sys_oper_log | M33: =VLOOKUP([資料表詳細]資料表詳細表格[[#This Row],[屬性類型(Postgre)]],選單!$A$3:$B$20,2,FALSE) -> string | N33: =CONCATENATE(參考!B$2,[資料表詳細]資料表詳細表格[[#This Row],[欄位名稱(英)]]) -> ins_user
A34: 31 | B34: System | C34: sys_oper_log | D34: 7 | E34: ins_time | F34: 資料新增時間 | G34: timestamp without time zone | I34: N | L34: =CONCATENATE(參考!B$1,[資料表詳細]資料表詳細表格[[#This Row],[表名]]) -> sys_oper_log | M34: =VLOOKUP([資料表詳細]資料表詳細表格[[#This Row],[屬性類型(Postgre)]],選單!$A$3:$B$20,2,FALSE) -> DateTime | N34: =CONCATENATE(參考!B$2,[資料表詳細]資料表詳細表格[[#This Row],[欄位名稱(英)]]) -> ins_time
A35: 32 | B35: System | C35: sys_oper_log | D35: 8 | E35: upd_user | F35: 資料修改人員 | G35: character varying | H35: 20 | I35: N | L35: =CONCATENATE(參考!B$1,[資料表詳細]資料表詳細表格[[#This Row],[表名]]) -> sys_oper_log | M35: =VLOOKUP([資料表詳細]資料表詳細表格[[#This Row],[屬性類型(Postgre)]],選單!$A$3:$B$20,2,FALSE) -> string | N35: =CONCATENATE(參考!B$2,[資料表詳細]資料表詳細表格[[#This Row],[欄位名稱(英)]]) -> upd_user
A36: 33 | B36: System | C36: sys_oper_log | D36: 9 | E36: upd_time | F36: 資料修改時間 | G36: timestamp without time zone | I36: N | L36: =CONCATENATE(參考!B$1,[資料表詳細]資料表詳細表格[[#This Row],[表名]]) -> sys_oper_log | M36: =VLOOKUP([資料表詳細]資料表詳細表格[[#This Row],[屬性類型(Postgre)]],選單!$A$3:$B$20,2,FALSE) -> DateTime | N36: =CONCATENATE(參考!B$2,[資料表詳細]資料表詳細表格[[#This Row],[欄位名稱(英)]]) -> upd_time
A37: 34 | B37: System | C37: sys_oper_log_history | D37: 1 | E37: log_id | F37: 事件紀錄編號 | G37: uuid | I37: N | J37: PK | L37: =CONCATENATE(參考!B$1,[資料表詳細]資料表詳細表格[[#This Row],[表名]]) -> sys_oper_log_history | M37: =VLOOKUP([資料表詳細]資料表詳細表格[[#This Row],[屬性類型(Postgre)]],選單!$A$3:$B$20,2,FALSE) -> Guid | N37: =CONCATENATE(參考!B$2,[資料表詳細]資料表詳細表格[[#This Row],[欄位名稱(英)]]) -> log_id
A38: 35 | B38: System | C38: sys_oper_log_history | D38: 2 | E38: account_id | F38: 操作人員 | G38: character varying | H38: 20 | I38: N | L38: =CONCATENATE(參考!B$1,[資料表詳細]資料表詳細表格[[#This Row],[表名]]) -> sys_oper_log_history | M38: =VLOOKUP([資料表詳細]資料表詳細表格[[#This Row],[屬性類型(Postgre)]],選單!$A$3:$B$20,2,FALSE) -> string | N38: =CONCATENATE(參考!B$2,[資料表詳細]資料表詳細表格[[#This Row],[欄位名稱(英)]]) -> account_id
A39: 36 | B39: System | C39: sys_oper_log_history | D39: 3 | E39: account_name | F39: 使用者姓名 | G39: text | I39: N | K39: 必須不依賴ID,萬一腳色被刪除仍可查找 | L39: =CONCATENATE(參考!B$1,[資料表詳細]資料表詳細表格[[#This Row],[表名]]) -> sys_oper_log_history | M39: =VLOOKUP([資料表詳細]資料表詳細表格[[#This Row],[屬性類型(Postgre)]],選單!$A$3:$B$20,2,FALSE) -> string | N39: =CONCATENATE(參考!B$2,[資料表詳細]資料表詳細表格[[#This Row],[欄位名稱(英)]]) -> account_name
A40: 37 | B40: System | C40: sys_oper_log_history | D40: 4 | E40: oper_id | F40: 操作識別代碼 | G40: character varying | H40: 40 | I40: N | L40: =CONCATENATE(參考!B$1,[資料表詳細]資料表詳細表格[[#This Row],[表名]]) -> sys_oper_log_history | M40: =VLOOKUP([資料表詳細]資料表詳細表格[[#This Row],[屬性類型(Postgre)]],選單!$A$3:$B$20,2,FALSE) -> string | N40: =CONCATENATE(參考!B$2,[資料表詳細]資料表詳細表格[[#This Row],[欄位名稱(英)]]) -> oper_id
...

Sheet 選單
A1: 資料表詳細 | G1: 告警 | J1: 位置清單 | O1: 通訊子系統 | R1: 資料表類別 | U1: CMFT畫面類別 | X1: 廣播 | AD1: 點矩陣-預錄訊息/即時訊息 | AS1: 點矩陣-列車訊息 | BL1: 直線電話 | BQ1: 列車 | BT1: 列車設備類型
A2: Postgre | B2: Csharp | C2: 鍵值設定 | D2: 空值 | E2: 布林 | G2: 告警等級 | H2: 告警等級表示 | J2: region_id | K2: region_name | L2: place_name | M2: area_name | O2: 編號 | P2: 系統名稱 | R2: 編號 | S2: 類別名稱 | U2: 編號 | V2: 類別名稱 | X2: 預錄語音 | AA2: 時段 | AD2: 基本設定 | AJ2: 中文設定 | AN2: 英文設定 | AS2: 基本設定 | AY2: 中文設定 | BC2: 英文設定 | BG2: 其他 | BL2: 通話狀態 | BQ2: 列車營運狀態 | BR2: 列車方向 | BT2: 乘客通訊控制設備(TCCU)
A3: boolean | B3: bool | C3: PK | D3: Y | E3: true | G3: 1 | H3: 重大 | J3: DepotMCB | K3: 金城機廠_管理中心大樓 | L3: 四層 | M3: 通訊設備機房 | O3: CTS | P3: 通訊光纖傳輸系統 | R3: CMFT | S3: 通訊系統多功能操作系統 | U3: Overview | V3: 狀態總覽 | X3: 類型 | Z3: 優先等級 | AA3: 編號 | AB3: 顯示文字 | AD3: 類型 | AF3: 優先等級 | AG3: 移動方式 | AI3: 移動速度 | AJ3: 字型 | AK3: 大小 | AM3: 顏色 | AN3: 字型 | AO3: 大小 | AQ3: 顏色 | AS3: 類型 | AU3: 優先等級 | AV3: 移動方式 | AX3: 移動速度 | AY3: 字型 | AZ3: 大小 | BB3: 顏色 | BC3: 字型 | BD3: 大小 | BF3: 顏色 | BG3: 子類型 | BI3: 顯示次數 | BJ3: 倒數顯示間格 | BL3: 編號 | BM3: 顯示文字 | BN3: 色碼 | BO3: 色碼HEX | BQ3: TRUE | BR3: UP | BT3: 網路交換器(LAN Switch)
A4: smallint | B4: short | C4: FK | D4: N | E4: false | G4: 2 | H4: 中度 | J4: DepotMCB | K4: 金城機廠_管理中心大樓 | L4: 五層 | M4: 行控中心 | O4: EPABX | P4: 自動電話系統 | R4: System | S4: 系統 | U4: PA | V4: 車站廣播 | X4: 編號 | Y4: 顯示文字 | AD4: 編號 | AE4: 顯示文字 | AG4: 編號 | AH4: 顯示文字 | AK4: 編號 | AL4: 顯示文字 | AO4: 編號 | AP4: 顯示文字 | AS4: 編號 | AT4: 顯示文字 | AV4: 編號 | AW4: 顯示文字 | AZ4: 編號 | BA4: 顯示文字 | BD4: 編號 | BE4: 顯示文字 | BG4: 編號 | BH4: 顯示文字 | BL4: 0 | BM4: 閒置 | BN4: 97, 97, 97 | BO4: #616161 | BQ4: FALSE | BR4: DN | BT4: 通訊操控面盤(TOCP)
A5: integer | B5: int | G5: 3 | H5: 輕微 | J5: DepotREP | K5: 金城機廠_維修工廠 | L5: 地下一層 | M5: 號誌工廠 | O5: DLTS | P5: 直線電話系統 | R5: PA | S5: 廣播 | U5: DMD | V5: 車站看板 | BL5: 4 | BM5: 待接聽 | BN5: 244, 185, 25 | BO5: #F4B919 | BT5: 緊急對講機(PIC)
A6: bigint | B6: long2 | J6: LG01 | K6: 中正紀念堂站 | L6: 月台層 | M6: 上行月台 | O6: DAR | P6: 錄音設備系統 | R6: DMD | S6: 車站點矩陣 | U6: OTCSTetra | V6: 列車通訊 | X6: 1 | Y6: 一般 | Z6: 1 | AA6: 1 | AB6: 尖峰時段 | AD6: 1 | AE6: 緊急訊息 | AF6: 1 | AG6: 1 | AH6: 上翻 | AI6: 1 | AJ6: 標楷體 | AK6: 1 | AL6: 小 | AM6: 紅 | AN6: Arial | AO6: 1 | AP6: 小 | AQ6: 紅 | AS6: 1 | AT6: 一般站大廳 | AU6: 1 | AV6: 1 | AW6: 上翻 | AX6: 1 | AY6: 標楷體 | AZ6: 1 | BA6: 小 | BB6: 紅 | BC6: Arial | BD6: 1 | BE6: 小 | BF6: 紅 | BG6: 11 | BH6: 班車靠站 | BI6: 1 | BJ6: 1 | BL6: 5 | BM6: 撥號中 | BN6: 198, 89, 17 | BO6: #C65911 | BT6: 攝影機(Camera)
A7: real | B7: float | J7: LG01 | K7: 中正紀念堂站 | L7: 月台層 | M7: 下行月台 | O7: CCTV | P7: 閉路電視系統 | R7: OTCS | S7: 列車通訊系統 | U7: Sync | V7: 同步播送 | X7: 2 | Y7: 緊急 | Z7: 2 | AA7: 2 | AB7: 離峰時段 | AD7: 2 | AE7: 誤點 | AF7: 2 | AG7: 2 | AH7: 下翻 | AI7: 2 | AJ7: 新細明體 | AK7: 2 | AL7: 中 | AM7: 綠 | AN7: Calibri | AO7: 2 | AP7: 中 | AQ7: 綠 | AS7: 2 | AT7: 一般站月台 | AU7: 2 | AV7: 2 | AW7: 下翻 | AX7: 2 | AY7: 新細明體 | AZ7: 2 | BA7: 中 | BB7: 綠 | BC7: Calibri | BD7: 2 | BE7: 中 | BF7: 綠 | BG7: 12 | BH7: 班車多久到站 | BI7: 2 | BJ7: 2 | BL7: 6 | BM7: 通話中 | BN7: 56, 176, 53 | BO7: #38B035 | BT7: 無線傳輸設備(Wi-Fi AP) | BV7: 告警狀態 | BX7: 告警級別1(高) | BY7: 告警級別2(中) | BZ7: 告警級別3(低)
A8: double precision | B8: double | J8: LG01 | K8: 中正紀念堂站 | L8: 地面層 | M8: 未知 | O8: DMD | P8: 點矩陣顯示器系統 | R8: TETRA | S8: 數位無線電系統 | U8: DLTS | V8: 直線電話 | Z8: 3 | AA8: 3 | AB8: 夜間時段 | AD8: 3 | AE8: 乘客須知 | AF8: 3 | AG8: 3 | AH8: 右移 | AI8: 3 | AJ8: 微軟正黑體 | AK8: 3 | AL8: 大 | AM8: 藍 | AN8: TimesNewRoman | AO8: 3 | AP8: 大 | AQ8: 藍 | AS8: 3 | AT8: 終端站大廳 | AU8: 3 | AV8: 3 | AW8: 右移 | AX8: 3 | AY8: 微軟正黑體 | AZ8: 3 | BA8: 大 | BB8: 藍 | BC8: TimesNewRoman | BD8: 3 | BE8: 大 | BF8: 藍 | BG8: 13 | BH8: 班車離站 | BI8: 3 | BJ8: 3 | BL8: 10 | BM8: 通話保留 | BN8: 1, 122, 177 | BO8: #017AB1 | BT8: 數位錄影設備(NVR) | BV8: 出現異常/未確認 | BW8: 文字 | BX8: 黑色 | BY8: 黑色 | BZ8: 黑色
A9: numeric | B9: decimal | J9: LG01 | K9: 中正紀念堂站 | L9: 穿堂層 | M9: 通訊號誌設備室 | O9: PA | P9: 廣播系統 | R9: DLTS | S9: 直線電 | U9: CCTV | V9: 閉路電視 | Z9: 4 | AD9: 4 | AE9: 政令宣導 | AF9: 4 | AG9: 4 | AH9: 左移 | AI9: 4 | AM9: 黃 | AQ9: 黃 | AS9: 4 | AT9: 終端站月台 | AU9: 4 | AV9: 4 | AW9: 左移 | AX9: 4 | BB9: 黃 | BF9: 黃 | BG9: 14 | BH9: 已無列車 | BI9: 4 | BJ9: 4 | BT9: 數位錄影設備(NVR)硬碟 | BW9: 底色 | BX9: 紅、灰閃爍 | BY9: 橘、灰閃爍 | BZ9: 黃、灰閃爍
A10: money | B10: decimal | J10: LG01 | K10: 中正紀念堂站 | L10: 穿堂層 | M10: 大廳站內 | O10: TETRA | P10: 數位無線電系統 | R10: CCTV | S10: 閉路電視 | U10: System | V10: 系統 | Z10: 5 | AD10: 5 | AE10: 商業廣告 | AF10: 5 | AI10: 5 | AU10: 5 | AX10: 5 | BG10: 21 | BH10: 班車即將到站 | BI10: 5 | BJ10: 5 | BT10: 視訊控制設備(VMS) | BV10: 出現異常/已確認 | BW10: 文字 | BX10: 黑色 | BY10: 黑色 | BZ10: 黑色
A11: text | B11: string | J11: LG01 | K11: 中正紀念堂站 | L11: 穿堂層 | M11: 大廳站外 | O11: CMFT | P11: 通訊系統多功能操作系統 | R11: Sync | S11: 同步播送 | AD11: 6 | AE11: 其他 | BG11: 22 | BH11: 班車到站 | BL11: 電話服務狀態 | BT11: 視訊控制設備(VMS)硬碟 | BW11: 底色 | BX11: 紅色 | BY11: 橘色 | BZ11: 黃色
A12: character varying | B12: string | J12: LG01 | K12: 中正紀念堂站 | L12: 穿堂層 | M12: 詢問處 | O12: OTCS | P12: 列車通訊系統 | BG12: 23 | BH12: 班車即將離站 | BL12: 0：空閒 | BT12: 乙太網路交換器(Switch) | BV12: 異常已恢復/未確認 | BW12: 文字 | BX12: 紅色 | BY12: 橘色 | BZ12: 黃色
A13: character | B13: string | J13: LG01 | K13: 中正紀念堂站 | L13: 軌道層 | M13: 未知 | O13: EMU | P13: 電聯車系統 | BG13: 24 | BH13: 不提供載客服務 | BL13: 1：由忙碌轉空閒延時狀態 | BT13: 軌旁無線傳輸設備(Wi-Fi AP) | BW13: 底色 | BX13: 灰色 | BY13: 灰色 | BZ13: 灰色
A14: citext | B14: string | J14: LG01 | K14: 中正紀念堂站 | L14: 頂版層 | M14: 通訊維修員工室 | O14: CLOCK | P14: 時鐘系統 | BG14: 25 | BH14: 班車多久到站 | BL14: 2：撥入佔用 | BT14: 緊急對講機(PIC) | BV14: 異常已恢復/已確認 | BW14: 文字 | BX14: 不顯示 | BY14: 不顯示 | BZ14: 不顯示
A15: json | B15: string | J15: LG01 | K15: 中正紀念堂站 | L15: 頂版層 | M15: 連通道 | BG15: 31 | BH15: 班車離站 | BL15: 3：撥出佔用
A16: jsonb | B16: string | J16: LG02 | K16: 植物園站 | L16: 月台層 | M16: 上行月台 | BG16: 32 | BH16: 班車多久發車 | BL16: 4：撥入響鈴
A17: xml | B17: string | J17: LG02 | K17: 植物園站 | L17: 月台層 | M17: 下行月台 | BG17: 33 | BH17: 已無列車 | BL17: 5：撥出響鈴 | BV17: 0
A18: uuid | B18: Guid | J18: LG02 | K18: 植物園站 | L18: 月台層 | M18: 通訊號誌設備室 | BG18: 41 | BH18: 班車即將到站 | BL18: 6：電話接通狀態 | BV18: 1
A19: bytea | B19: byte[] | J19: LG02 | K19: 植物園站 | L19: 地面層 | M19: 未知 | BG19: 42 | BH19: 班車到站 | BL19: 7：等待坐席電話掛機 | BV19: 2
A20: timestamp without time zone | B20: DateTime | J20: LG02 | K20: 植物園站 | L20: 穿堂層 | M20: 大廳站內 | BG20: 43 | BH20: 班車即將離站 | BL20: 8：放音狀態 | BV20: 3
J21: LG02 | K21: 植物園站 | L21: 穿堂層 | M21: 大廳站外 | BL21: 9：話後處理 | BV21: 4
A22: Guid生成 | J22: LG02 | K22: 植物園站 | L22: 軌道層 | M22: 未知 | BL22: 10：保留狀態 | BV22: 5
A23: =LOWER(CONCATENATE(DEC2HEX(RANDBETWEEN(0,POWER(16,8)),8),"-",DEC2HEX(RANDBETWEEN(0,POWER(16,4)),4),"-","4",DEC2HEX(RANDBETWEEN(0,POWER(16,3)),3),"-",DEC2HEX(RANDBETWEEN(8,11)),DEC2HEX(RANDBETWEEN(0,POWER(16,3)),3),"-",DEC2HEX(RANDBETWEEN(0,POWER(16,8)),8),DEC2HEX(RANDBETWEEN(0,POWER(16,4)),4))) -> 6d196da7-473e-4805-bc5f-39ce2da9dc48 | J23: LG02 | K23: 植物園站 | L23: 設備層 | M23: 未知 | BL23: 11：等待IVR返回狀態 | BV23: 6
A24: =LOWER(CONCATENATE(DEC2HEX(RANDBETWEEN(0,POWER(16,8)),8),"-",DEC2HEX(RANDBETWEEN(0,POWER(16,4)),4),"-","4",DEC2HEX(RANDBETWEEN(0,POWER(16,3)),3),"-",DEC2HEX(RANDBETWEEN(8,11)),DEC2HEX(RANDBETWEEN(0,POWER(16,3)),3),"-",DEC2HEX(RANDBETWEEN(0,POWER(16,8)),8),DEC2HEX(RANDBETWEEN(0,POWER(16,4)),4))) -> 22d2419f-44a5-4dd4-a5c1-16c81165ed34 | J24: LG03 | K24: 廈安站 | L24: 月台層 | M24: 上行月台 | BL24: 12：摘機狀態 | BV24: 7
A25: =LOWER(CONCATENATE(DEC2HEX(RANDBETWEEN(0,POWER(16,8)),8),"-",DEC2HEX(RANDBETWEEN(0,POWER(16,4)),4),"-","4",DEC2HEX(RANDBETWEEN(0,POWER(16,3)),3),"-",DEC2HEX(RANDBETWEEN(8,11)),DEC2HEX(RANDBETWEEN(0,POWER(16,3)),3),"-",DEC2HEX(RANDBETWEEN(0,POWER(16,8)),8),DEC2HEX(RANDBETWEEN(0,POWER(16,4)),4))) -> de21967b-90f4-4e79-982b-20134644c8d3 | J25: LG03 | K25: 廈安站 | L25: 月台層 | M25: 下行月台 | BV25: 8
A26: =LOWER(CONCATENATE(DEC2HEX(RANDBETWEEN(0,POWER(16,8)),8),"-",DEC2HEX(RANDBETWEEN(0,POWER(16,4)),4),"-","4",DEC2HEX(RANDBETWEEN(0,POWER(16,3)),3),"-",DEC2HEX(RANDBETWEEN(8,11)),DEC2HEX(RANDBETWEEN(0,POWER(16,3)),3),"-",DEC2HEX(RANDBETWEEN(0,POWER(16,8)),8),DEC2HEX(RANDBETWEEN(0,POWER(16,4)),4))) -> e064802c-d096-460d-9e43-e7cffe896dc2 | J26: LG03 | K26: 廈安站 | L26: 穿堂層 | M26: 通訊號誌設備室 | BV26: 9
A27: =LOWER(CONCATENATE(DEC2HEX(RANDBETWEEN(0,POWER(16,8)),8),"-",DEC2HEX(RANDBETWEEN(0,POWER(16,4)),4),"-","4",DEC2HEX(RANDBETWEEN(0,POWER(16,3)),3),"-",DEC2HEX(RANDBETWEEN(8,11)),DEC2HEX(RANDBETWEEN(0,POWER(16,3)),3),"-",DEC2HEX(RANDBETWEEN(0,POWER(16,8)),8),DEC2HEX(RANDBETWEEN(0,POWER(16,4)),4))) -> 19332e6e-6de5-4261-95aa-0d499b54df2c | J27: LG03 | K27: 廈安站 | L27: 穿堂層 | M27: 大廳站內 | BV27: 10
A28: =LOWER(CONCATENATE(DEC2HEX(RANDBETWEEN(0,POWER(16,8)),8),"-",DEC2HEX(RANDBETWEEN(0,POWER(16,4)),4),"-","4",DEC2HEX(RANDBETWEEN(0,POWER(16,3)),3),"-",DEC2HEX(RANDBETWEEN(8,11)),DEC2HEX(RANDBETWEEN(0,POWER(16,3)),3),"-",DEC2HEX(RANDBETWEEN(0,POWER(16,8)),8),DEC2HEX(RANDBETWEEN(0,POWER(16,4)),4))) -> 73d13dc1-ac17-414c-b6b9-f88ac1819d6b | J28: LG03 | K28: 廈安站 | L28: 穿堂層 | M28: 大廳站外
A29: =LOWER(CONCATENATE(DEC2HEX(RANDBETWEEN(0,POWER(16,8)),8),"-",DEC2HEX(RANDBETWEEN(0,POWER(16,4)),4),"-","4",DEC2HEX(RANDBETWEEN(0,POWER(16,3)),3),"-",DEC2HEX(RANDBETWEEN(8,11)),DEC2HEX(RANDBETWEEN(0,POWER(16,3)),3),"-",DEC2HEX(RANDBETWEEN(0,POWER(16,8)),8),DEC2HEX(RANDBETWEEN(0,POWER(16,4)),4))) -> cc9ab4eb-56bb-4027-8c6e-24220baf026c | J29: LG03 | K29: 廈安站 | L29: 軌道層 | M29: 未知
A30: =LOWER(CONCATENATE(DEC2HEX(RANDBETWEEN(0,POWER(16,8)),8),"-",DEC2HEX(RANDBETWEEN(0,POWER(16,4)),4),"-","4",DEC2HEX(RANDBETWEEN(0,POWER(16,3)),3),"-",DEC2HEX(RANDBETWEEN(8,11)),DEC2HEX(RANDBETWEEN(0,POWER(16,3)),3),"-",DEC2HEX(RANDBETWEEN(0,POWER(16,8)),8),DEC2HEX(RANDBETWEEN(0,POWER(16,4)),4))) -> 27075a3c-6a49-4c2a-abab-c824d1afde46 | J30: LG03 | K30: 廈安站 | L30: 頂版層 | M30: 未知
A31: =LOWER(CONCATENATE(DEC2HEX(RANDBETWEEN(0,POWER(16,8)),8),"-",DEC2HEX(RANDBETWEEN(0,POWER(16,4)),4),"-","4",DEC2HEX(RANDBETWEEN(0,POWER(16,3)),3),"-",DEC2HEX(RANDBETWEEN(8,11)),DEC2HEX(RANDBETWEEN(0,POWER(16,3)),3),"-",DEC2HEX(RANDBETWEEN(0,POWER(16,8)),8),DEC2HEX(RANDBETWEEN(0,POWER(16,4)),4))) -> 6ccfecac-c3c8-4365-b206-675f5274b27b | J31: LG04 | K31: 加蚋站 | L31: 月台層 | M31: 上行月台
A32: =LOWER(CONCATENATE(DEC2HEX(RANDBETWEEN(0,POWER(16,8)),8),"-",DEC2HEX(RANDBETWEEN(0,POWER(16,4)),4),"-","4",DEC2HEX(RANDBETWEEN(0,POWER(16,3)),3),"-",DEC2HEX(RANDBETWEEN(8,11)),DEC2HEX(RANDBETWEEN(0,POWER(16,3)),3),"-",DEC2HEX(RANDBETWEEN(0,POWER(16,8)),8),DEC2HEX(RANDBETWEEN(0,POWER(16,4)),4))) -> cf405269-6ae9-4e8c-8b8c-b2289bb78e09 | J32: LG04 | K32: 加蚋站 | L32: 月台層 | M32: 下行月台
A33: =LOWER(CONCATENATE(DEC2HEX(RANDBETWEEN(0,POWER(16,8)),8),"-",DEC2HEX(RANDBETWEEN(0,POWER(16,4)),4),"-","4",DEC2HEX(RANDBETWEEN(0,POWER(16,3)),3),"-",DEC2HEX(RANDBETWEEN(8,11)),DEC2HEX(RANDBETWEEN(0,POWER(16,3)),3),"-",DEC2HEX(RANDBETWEEN(0,POWER(16,8)),8),DEC2HEX(RANDBETWEEN(0,POWER(16,4)),4))) -> 862f7068-5bed-4890-bd52-4842d88872ba | J33: LG04 | K33: 加蚋站 | L33: 穿堂層 | M33: 大廳站內
A34: =LOWER(CONCATENATE(DEC2HEX(RANDBETWEEN(0,POWER(16,8)),8),"-",DEC2HEX(RANDBETWEEN(0,POWER(16,4)),4),"-","4",DEC2HEX(RANDBETWEEN(0,POWER(16,3)),3),"-",DEC2HEX(RANDBETWEEN(8,11)),DEC2HEX(RANDBETWEEN(0,POWER(16,3)),3),"-",DEC2HEX(RANDBETWEEN(0,POWER(16,8)),8),DEC2HEX(RANDBETWEEN(0,POWER(16,4)),4))) -> dc42f008-da92-444f-8f85-c946f00786d5 | J34: LG04 | K34: 加蚋站 | L34: 穿堂層 | M34: 大廳站外
A35: =LOWER(CONCATENATE(DEC2HEX(RANDBETWEEN(0,POWER(16,8)),8),"-",DEC2HEX(RANDBETWEEN(0,POWER(16,4)),4),"-","4",DEC2HEX(RANDBETWEEN(0,POWER(16,3)),3),"-",DEC2HEX(RANDBETWEEN(8,11)),DEC2HEX(RANDBETWEEN(0,POWER(16,3)),3),"-",DEC2HEX(RANDBETWEEN(0,POWER(16,8)),8),DEC2HEX(RANDBETWEEN(0,POWER(16,4)),4))) -> 186bf9d0-40d8-4b8f-b4e5-48f02c759a59 | J35: LG04 | K35: 加蚋站 | L35: 地面層 | M35: 未知
J36: LG04 | K36: 加蚋站 | L36: 軌道層 | M36: 未知
J37: LG04 | K37: 加蚋站 | L37: 設備層 | M37: 通訊號誌設備室
J38: LG05 | K38: 永和永平國小站 | L38: 月台層 | M38: 上行月台
J39: LG05 | K39: 永和永平國小站 | L39: 月台層 | M39: 下行月台
J40: LG05 | K40: 永和永平國小站 | L40: 穿堂層 | M40: 大廳站內
...

Sheet message_group
A1: message_group
A2: id | B2: group_name
A3: 語音群組編號 | B3: 語音群組名稱
A4: 6f6874cb-04e3-44cf-ad17-c1e45d961e5e | B4: 不要飲食
A5: 5cf03fe4-b462-4dd4-819d-3630c07e5d65 | B5: 單程票使用
A6: 8dd6f0db-ac4b-41a3-9332-a49406b4fba5 | B6: 行動不便改搭電梯
A7: 6fb9992d-20ec-4894-887f-59f006902e30 | B7: 電扶梯靠右

Sheet message
A1: message
A2: id | B2: name | C2: content | D2: belong_group_id | E2: is_use_du
A3: 訊息編號 | B3: 訊息名稱 | C3: 中文訊息內容 | D3: 所屬群組編號 | E3: 是否使用DU
A4: 6f6874cb-04e3-44cf-ad17-c1e45d961e5e | B4: 不要飲食 | C4: 各位旅客您好，為維護環境清潔，請不要在車站及列車上吃東西、喝飲料、嚼口香糖或檳榔。 | E4: FALSE
A5: 5cf03fe4-b462-4dd4-819d-3630c07e5d65 | B5: 單程票使用 | C5: 各位旅客您好，使用單程票時請將車票輕觸感應區後進站，出站時，車票會自動回收，謝謝您的支持與配合。 | E5: FALSE
A6: 8dd6f0db-ac4b-41a3-9332-a49406b4fba5 | B6: 行動不便改搭電梯 | C6: 各位旅客您好，由於電扶梯移動速度較快，年長及行動不便的旅客請儘量改搭電梯，以維護您的安全。 | E6: FALSE
A7: 6fb9992d-20ec-4894-887f-59f006902e30 | B7: 電扶梯靠右 | C7: 各位旅客請注意，搭乘電扶梯時，請靠右站立保持左側淨空並緊握扶手，謝謝您的支持與配合。 | E7: FALSE
A8: 3a95e281-393a-4939-9fe7-80a3dfd454e2 | B8: 照顧好小孩 | C8: 各位旅客您好，為了維持秩序與安全，請照顧好您的小孩，不要讓他們在車站及列車上奔跑，以免發生危險，謝謝您的支持與配合。 | E8: FALSE
A9: a6f0506b-81f9-4e7b-b017-c33d4be3b3fa | B9: 候車線排隊 | C9: 您好，候車時，請於白色候車線後方依序排隊，謝謝。 | E9: FALSE
A10: 2b3cd3d1-abd3-40bb-a541-0957d535fc68 | B10: 下車再上車 | C10: 各位旅客您好，搭車時請禮讓車上旅客下車再依序上車，謝謝您的支持與配合。 | E10: FALSE
A11: b6532612-2f97-4385-9fae-1135da1bf323 | B11: 人潮眾多分散候車 | C11: 各位旅客您好，因為現在人潮眾多，請各位旅客分散到各車廂門候車，以避免擁擠，謝謝您的支持與配合。 | E11: FALSE
A12: 54d3d3d9-6b86-4796-8836-90c578c78326 | B12: 分散候車 | C12: 您好，月台候車時，請分散候車位置，以節省您的上下車時間，謝謝。 | E12: FALSE
A13: dc719bbc-d87b-4b77-bc54-073b9d9b9dbe | B13: 因故暫停服務 | C13: 各位旅客請注意，本站因故將暫停服務，請遵照服務人員的引導，迅速離開車站，謝謝您的支持與配合。 | E13: FALSE
A14: 13509ddc-21a6-4316-83cc-27b3c1e4d4dd | B14: 緊急事故 | C14: 各位旅客請注意，各位旅客請注意，由於車站內發生緊急事故，為了您的安全，請迅速離開車站。 | E14: FALSE
A15: 8815fecc-bd88-4353-a984-d56a1ce163f6 | B15: 事故後續辦理 | C15: 各位旅客請注意，因本次事故而離開車站的旅客，您所持用的悠遊卡可繼續使用，不扣除本次旅程費用；持用單程票的旅客，請在一週內向車站辦理退票。 | E15: FALSE
... A98: 23081968-045c-44e1-9aea-58bd915971c8 | B98: 颱風期間 | C98: 各位旅客請注意：颱風期間為確保您的安全，當風力過大時，高架、平面區段將暫停營運，請您隨時留意車站訊息。 | E98: FALSE

Sheet voice_group
A1: voice_group
A2: id | B2: group_name
A3: 訊息群組編號 | B3: 訊息群組名稱
A4: 1f2a4c2b-3d54-47a7-a2d2-bd8e52968485 | B4: 政令宣導
A5: a3d3e0f1-ec1c-4a55-a5cf-70f5fd0122cc | B5: 安全宣導
A6: 67825cc7-f1a6-4d65-b3c4-03a0c39e021a | B6: 衛生宣導
A7: c216b73b-ff5a-4d82-b81a-04207b57910a | B7: 活動訊息
A8: ec51aef7-09d3-4714-93ee-73913b9497e9 | B8: 測試

Sheet voice
A1: voice
A2: id | B2: name | C2: content | E2: belong_group_id | F2: is_use_du
A3: 訊息編號 | B3: 訊息名稱 | C3: 中文訊息內容 | E3: 所屬群組編號 | F3: 是否使用DU
A4: 6f6874cb-04e3-44cf-ad17-c1e45d961e5e | B4: 不要飲食 | C4: 各位旅客您好，為維護環境清潔，請不要在車站及列車上吃東西、喝飲料、嚼口香糖或檳榔。 | F4: FALSE
A5: 5cf03fe4-b462-4dd4-819d-3630c07e5d65 | B5: 單程票使用 | C5: 各位旅客您好，使用單程票時請將車票輕觸感應區後進站，出站時，車票會自動回收，謝謝您的支持與配合。 | F5: FALSE
A6: 8dd6f0db-ac4b-41a3-9332-a49406b4fba5 | B6: 行動不便改搭電梯 | C6: 各位旅客您好，由於電扶梯移動速度較快，年長及行動不便的旅客請儘量改搭電梯，以維護您的安全。 | F6: FALSE

Sheet role
A13: role
A14: message_id | B14: message_name | C14: message_content | D14: is_use_du
A15: 訊息編號 | B15: 訊息名稱 | C15: 中文訊息內容 | D15: 是否使用DU
A16: 6f6874cb-04e3-44cf-ad17-c1e45d961e5e | B16: 不要飲食 | C16: 各位旅客您好，為維護環境清潔，請不要在車站及列車上吃東西、喝飲料、嚼口香糖或檳榔。 | D16: FALSE
A17: 5cf03fe4-b462-4dd4-819d-3630c07e5d65 | B17: 單程票使用 | C17: 各位旅客您好，使用單程票時請將車票輕觸感應區後進站，出站時，車票會自動回收，謝謝您的支持與配合。 | D17: FALSE
A18: 8dd6f0db-ac4b-41a3-9332-a49406b4fba5 | B18: 行動不便改搭電梯 | C18: 各位旅客您好，由於電扶梯移動速度較快，年長及行動不便的旅客請儘量改搭電梯，以維護您的安全。 | D18: FALSE
A19: 6fb9992d-20ec-4894-887f-59f006902e30 | B19: 電扶梯靠右 | C19: 各位旅客請注意，搭乘電扶梯時，請靠右站立保持左側淨空並緊握扶手，謝謝您的支持與配合。 | D19: FALSE
A20: 3a95e281-393a-4939-9fe7-80a3dfd454e2 | B20: 照顧好小孩 | C20: 各位旅客您好，為了維持秩序與安全，請照顧好您的小孩，不要讓他們在車站及列車上奔跑，以免發生危險，謝謝您的支持與配合。 | D20: FALSE
A21: a6f0506b-81f9-4e7b-b017-c33d4be3b3fa | B21: 候車線排隊 | C21: 您好，候車時，請於白色候車線後方依序排隊，謝謝。 | D21: FALSE

Sheet user

Sheet 資料表模板
F1: 表格名稱3
F2: [PK]欄位名(英)1 | G2: 欄位名(英)2 | H2: 欄位名(英)3
F3: 欄位名(中)1 | G3: 欄位名(中)2 | H3: 欄位名(中)3 | I3: delete sql | J3: insert sql
I4: =CONCATENATE("delete from dbo.",$F$1," where ",$F$2," = ","'",資料表表格3[[#This Row],[欄位名(中)1]],"';") -> delete from dbo.表格名稱3 where [PK]欄位名(英)1 = ''; | J4: =CONCATENATE( "insert into dbo.",$F$1," values(","'",資料表表格3[[#This Row],[欄位名(中)1]],"'",",","'",資料表表格3[[#This Row],[欄位名(中)2]],"'",",","'",資料表表格3[[#This Row],[欄位名(中)3]],"'",",'",參考!$B$5,"'",",",參考!$B$6,",","'",參考!$B$7,"'",",",參考!$B$8,");") -> insert into dbo.表格名稱3 values('','','','admin',clock_timestamp(),'admin',clock_timestamp());
I5: =CONCATENATE("delete from dbo.",$F$1," where ",$F$2," = ","'",資料表表格3[[#This Row],[欄位名(中)1]],"';") -> delete from dbo.表格名稱3 where [PK]欄位名(英)1 = ''; | J5: =CONCATENATE( "insert into dbo.",$F$1," values(","'",資料表表格3[[#This Row],[欄位名(中)1]],"'",",","'",資料表表格3[[#This Row],[欄位名(中)2]],"'",",","'",資料表表格3[[#This Row],[欄位名(中)3]],"'",",'",參考!$B$5,"'",",",參考!$B$6,",","'",參考!$B$7,"'",",",參考!$B$8,");") -> insert into dbo.表格名稱3 values('','','','admin',clock_timestamp(),'admin',clock_timestamp());
E7: 表格名稱4
E8: [PK]欄位名(英)1 | F8: 欄位名(英)2 | G8: 欄位名(英)3 | H8: 欄位名(英)4
E9: 欄位名(中)1 | F9: 欄位名(中)2 | G9: 欄位名(中)3 | H9: 欄位名(中)4 | I9: delete sql | J9: insert sql
I10: =CONCATENATE("delete from dbo.", $E$7," where ",$E$8," = ","'",資料表表格4[[#This Row],[欄位名(中)1]],"';") -> delete from dbo.表格名稱4 where [PK]欄位名(英)1 = ''; | J10: =CONCATENATE( "insert into dbo.",$E$7," values(","'",資料表表格4[[#This Row],[欄位名(中)1]],"'",",","'",資料表表格4[[#This Row],[欄位名(中)2]],"'",",","'",資料表表格4[[#This Row],[欄位名(中)3]],"'",",","'","","'",",'",參考!$B$5,"'",",",參考!$B$6,",","'",參考!$B$7,"'",",",參考!$B$8,");") -> insert into dbo.表格名稱4 values('','','','','admin',clock_timestamp(),'admin',clock_timestamp());
I11: =CONCATENATE("delete from dbo.", $E$7," where ",$E$8," = ","'",資料表表格4[[#This Row],[欄位名(中)1]],"';") -> delete from dbo.表格名稱4 where [PK]欄位名(英)1 = ''; | J11: =CONCATENATE( "insert into dbo.",$E$7," values(","'",資料表表格4[[#This Row],[欄位名(中)1]],"'",",","'",資料表表格4[[#This Row],[欄位名(中)2]],"'",",","'",資料表表格4[[#This Row],[欄位名(中)3]],"'",",","'","","'",",'",參考!$B$5,"'",",",參考!$B$6,",","'",參考!$B$7,"'",",",參考!$B$8,");") -> insert into dbo.表格名稱4 values('','','','','admin',clock_timestamp(),'admin',clock_timestamp());
D13: 表格名稱5
D14: [PK]欄位名(英)1 | E14: 欄位名(英)2 | F14: 欄位名(英)3 | G14: 欄位名(英)4 | H14: 欄位名(英)5
D15: 欄位名(中)1 | E15: 欄位名(中)2 | F15: 欄位名(中)3 | G15: 欄位名(中)4 | H15: 欄位名(中)5 | I15: delete sql | J15: insert sql
I16: =CONCATENATE("delete from dbo.", $D$13," where ",$D$14," = ","'",資料表表格5[[#This Row],[欄位名(中)1]],"';") -> delete from dbo.表格名稱5 where [PK]欄位名(英)1 = ''; | J16: =CONCATENATE( "insert into dbo.",$D$13," values(","'",資料表表格5[[#This Row],[欄位名(中)1]],"'",",","'",資料表表格5[[#This Row],[欄位名(中)2]],"'",",","'",資料表表格5[[#This Row],[欄位名(中)3]],"'",",'",資料表表格5[[#This Row],[欄位名(中)4]],"'",",","'",資料表表格5[[#This Row],[欄位名(中)5]],"'",",'",參考!$B$5,"'",",",參考!$B$6,",","'",參考!$B$7,"'",",",參考!$B$8,");") -> insert into dbo.表格名稱5 values('','','','','','admin',clock_timestamp(),'admin',clock_timestamp());
I17: =CONCATENATE("delete from dbo.", $D$13," where ",$D$14," = ","'",資料表表格5[[#This Row],[欄位名(中)1]],"';") -> delete from dbo.表格名稱5 where [PK]欄位名(英)1 = ''; | J17: =CONCATENATE( "insert into dbo.",$D$13," values(","'",資料表表格5[[#This Row],[欄位名(中)1]],"'",",","'",資料表表格5[[#This Row],[欄位名(中)2]],"'",",","'",資料表表格5[[#This Row],[欄位名(中)3]],"'",",'",資料表表格5[[#This Row],[欄位名(中)4]],"'",",","'",資料表表格5[[#This Row],[欄位名(中)5]],"'",",'",參考!$B$5,"'",",",參考!$B$6,",","'",參考!$B$7,"'",",",參考!$B$8,");") -> insert into dbo.表格名稱5 values('','','','','','admin',clock_timestamp(),'admin',clock_timestamp());
C19: 表格名稱6
C20: [PK]欄位名(英)1 | D20: 欄位名(英)2 | E20: 欄位名(英)3 | F20: 欄位名(英)4 | G20: 欄位名(英)5 | H20: 欄位名(英)6
C21: 欄位名(中)1 | D21: 欄位名(中)2 | E21: 欄位名(中)3 | F21: 欄位名(中)4 | G21: 欄位名(中)5 | H21: 欄位名(中)6 | I21: delete sql | J21: insert sql
I22: =CONCATENATE("delete from dbo.", $C$19," where ",$C$20," = ","'",C22,"';") -> delete from dbo.表格名稱6 where [PK]欄位名(英)1 = ''; | J22: =CONCATENATE( "insert into dbo.",$C$19," values(","'", C22,"'",",","'",D22,"'",",","'",E22,"'",",","'",F22,"'",",","'",G22,"'",",","'",H22,"'",",'",參考!$B$5,"'",",",參考!$B$6,",","'",參考!$B$7,"'",",",參考!$B$8,");") -> insert into dbo.表格名稱6 values('','','','','','','admin',clock_timestamp(),'admin',clock_timestamp());
I23: =CONCATENATE("delete from dbo.", $C$19," where ",$C$20," = ","'",C23,"';") -> delete from dbo.表格名稱6 where [PK]欄位名(英)1 = ''; | J23: =CONCATENATE( "insert into dbo.",$C$19," values(","'", C23,"'",",","'",D23,"'",",","'",E23,"'",",","'",F23,"'",",","'",G23,"'",",","'",H23,"'",",'",參考!$B$5,"'",",",參考!$B$6,",","'",參考!$B$7,"'",",",參考!$B$8,");") -> insert into dbo.表格名稱6 values('','','','','','','admin',clock_timestamp(),'admin',clock_timestamp());

Sheet 參考
A1: 類名前綴
A2: 屬性名前綴
A3: using | B3: using System; using System.ComponentModel.DataAnnotations;
A4: namespace | B4: CMFTClientCore.Models
A5: ins_user | B5: admin
A6: ins_time | B6: clock_timestamp()
A7: upd_user | B7: admin
A8: upd_time | B8: clock_timestamp()
